Workbook

Sheet Project Showcase
B1: 🏆 DIGILIANS PORTFOLIO — STARTUP PROJECT SHOWCASE
B2: Official Startup Project Showcase & Team Profiles | Pitch Documentation
B4: 🚀 AEROMIND SENTINEL
B5: Startup Name | C5: AeroMind Sentinel
B6: Project Status | C6: Finalist
B7: Hackathon / Competition | C7: Creativa Alexandria: AI Hackathon – AI for Egypt Real Problems
B8: Team Name | C8: AeroMind AI
B10: 👥 TEAM MEMBERS & ROLES
B11: No. | C11: Name | F11: Role | H11: Contact Email
B12: 1 | C12: Mohamed Abd Elsalam Mohamed Gharieb | F12: Team Leader | H12: moghariebai@gmail.com
B13: 2 | C13: Aya Mostafa Ali Hassan | F13: AI Developer | H13: aya.mostafa.hassan@gmail.com
B14: 3 | C14: Aya Emad Ramadan Elsaby | F14: AI Developer | H14: aya.emad.elsaby@gmail.com
B15: 4 | C15: Eman Mansour Abdel Halim Barrin | F15: Signal Processing Specialist | H15: eman.mansour.barrin@gmail.com
B17: 💡 PROJECT OVERVIEW
B18: AeroMind Sentinel is an AI-powered autonomous drone intelligence system that transforms drones from traditional monitoring tools into intelligent agents capable of detecting incidents, analyzing risks, tracking targets, and generating real-time alerts using Computer Vision and AI technologies.
B19: Core Features & Pillars:
B20: • Artificial Intelligence & Computer Vision for incident detection
B21: • Autonomous Guidance Systems for real-time monitoring
B22: • Multi-object Target Tracking & dynamic route optimization
B23: • Instant safety response notifications and automated alerting systems
B25: 📊 BUSINESS Profile & Market Model
B26: Target Users | C26: Smart cities, traffic authorities, emergency response services, and public safety agencies.
B27: Paying Customers | C27: Government municipalities, private security firms, and highway administration authorities.
B28: Problem | C28: Traditional drone monitoring relies heavily on manual operator control and delayed video review, making it slow and error-prone in critical situations like accidents, security breaches, or infrastructure failures.
B29: Solution | C29: An autonomous, edge-computing AI system deployed on drones that automatically flags emergency events and maps coordinates to safety dispatch teams in real time without human review delays.
B30: Business Model | C30: B2B SaaS with hardware-integrated licensing for private operations and governmental projects.
B31: Revenue Streams | C31: Hardware subscription plans, custom software integration fees, and priority API access for governmental dashboards.
B33: ⚙️ TECHNOLOGY & AI ARCHITECTURE
B34: AI Architecture | C34: Computer Vision and Edge AI pipeline for low-latency target classification.
B35: Core Models | C35: YOLOv8 custom models for object detection, DeepSORT for tracking, and onboard flight controllers.
B36: Core Tech Stack | C36: Python, FastAPI, C++, OpenCV, PyTorch, ROS (Robot Operating System), Docker, WebSockets.
B39: 🚀 BINGOO AI
B40: Startup Name | C40: Bingoo AI
B41: Project Status | C41: Accepted / Approved for Hackathon Participation
B42: Hackathon / Competition | C42: Creativa Alexandria: AI Hackathon – AI for Egypt Real Problems
B43: Team Name | C43: Bingoo AI Team
B45: 👥 TEAM MEMBERS & ROLES
B46: No. | C46: Name | F46: Role | H46: Contact Email
B47: 1 | C47: Mohamed Abd Elsalam Mohamed Gharieb | F47: Team Leader | H47: moghariebai@gmail.com
B48: 2 | C48: Aya Mostafa Ali Hassan | F48: AI Developer | H48: aya.mostafa.hassan@gmail.com
...

Sheet Competition Submissions
A1: 🏆 Digilians Achievement Portal — Competition Submissions
A2: Master database for all student competition entries
A3: 📋 SUBMISSION INFO | G3: 👤 STUDENT DETAILS | M3: 🏅 COMPETITION INFO | U3: 📅 TIMELINE | Y3: 💡 PROJECT DETAILS | AD3: 👥 TEAM INFO | AG3: 👑 LEADER INFO | AK3: 🎖 ACHIEVEMENTS | AO3: 🔗 LINKS & DOCS | AS3: 📝 NOTES
A4: Submission ID | B4: Submission Date | C4: Last Updated | D4: Created By | E4: Academic Year | F4: Batch | G4: Student Full Name | H4: Student Email | I4: Student Phone | J4: Digilians Track | K4: University | L4: Faculty | M4: Competition Name | N4: Competition Link | O4: Organizer | P4: Competition Category | Q4: Competition Country | R4: Competition Type | S4: Competition Level | T4: Prize Pool | U4: Registration Date | V4: Submission Deadline | W4: Deadline Status | X4: Days Remaining | Y4: Project Name | Z4: Project Description | AA4: Technology Stack | AB4: Team Name | AC4: Total Team Members | AD4: Is Team Leader? | AE4: Team Leader Name | AF4: Team Leader Email | AG4: Team Leader Phone | AH4: Current Status | AI4: Achievement | AJ4: Ranking | AK4: Prize Won | AL4: Certificate Link | AM4: Demo Link | AN4: GitHub Repository | AO4: LinkedIn Post | AP4: Presentation Link | AQ4: Drive Folder | AR4: Notes | AS4: Completion %
A5: =IF(B5<>"","SUB-"&TEXT(ROW()+6,"0000"),"") | B5: 2026-06-26 | C5: 2026-06-26 00:00:00 | D5: Admin | E5: 4th Year | F5: Batch 3 | G5: Mohamed Abd Elsalam Mohamed Gharieb | H5: moghariebai@gmail.com | I5: +20 01022487565 | J5: AI & Machine Learning | K5: Alexandria University | L5: Faculty of Engineering | M5: ITC-EGYPT 2026 | N5: https://itc-egypt.org | O5: ITC Egypt | P5: AI & Machine Learning | Q5: Egypt | R5: Online | S5: National | T5: N/A | U5: 2026-02-15 | V5: 2026-08-31 | W5: =IF(V5="","N/A",IF(V5<TODAY(),"⛔ Expired",IF(V5-TODAY()<=7,"⚠️ Soon","✅ Open"))) | X5: =IF(V5="","",MAX(0,V5-TODAY())) | Y5: SADAR: AI-Powered Spectrum Anomaly Detection for Anti-Drone Threats | Z5: SADAR is an AI-powered autonomous spectrum intelligence platform designed for anti-drone threat detection. The system analyzes RF spectrum signals, detects abnormal patterns, classifies potential drone activities, and provides real-time intelligence through an AI analytics dashboard. | AA5: Python, FastAPI, React, TypeScript, AI/ML Models, Signal Processing, Data Analytics, WebSockets, Docker, REST API | AB5: SADAR AI Team | AC5: 5 | AD5: Yes | AE5: Mohamed Abd Elsalam Mohamed Gharieb | AF5: moghariebai@gmail.com | AG5: +20 01022487565 | AH5: Shortlisted | AI5: Passed First Stage Review and Advanced to Phase 2 | AJ5: Phase 2 Participant | AK5: N/A | AM5: To be added after final presentation recording | AN5: https://github.com/GhariebML/SADAR | AR5: SADAR successfully passed the first stage evaluation of ITC-EGYPT 2026 and advanced to Phase 2. The project is currently being prepared for final demonstration including system testing, UI/UX improvements, AI analytics validation, and professional video presentation. Team Leader Location: Montaza District, Alexandria, Egypt. Team Member Aya Ashraf Location: Ibn El Sayar Street, El Kabary, Alexandria, Egypt. | AS5: =COUNTA(G5:H5,M5,Y5,AH5)/5
A6: =IF(B6<>"","SUB-"&TEXT(ROW()+6,"0000"),"") | B6: 2026-06-26 | C6: 2026-06-26 00:00:00 | D6: Admin | E6: 4th Year | F6: Batch 3 | G6: Mohamed Abd Elsalam Mohamed Gharieb | H6: moghariebai@gmail.com | I6: +20 01022487565 | J6: AI & Machine Learning | K6: Alexandria University | L6: Faculty of Engineering | M6: ITC-EGYPT 2026 Anti-Drone Challenge | N6: https://itc-egypt.org | O6: ITC Egypt | P6: AI & Machine Learning | Q6: Egypt | R6: Online | S6: National | T6: N/A | U6: 2026-02-15 | V6: 2026-08-31 | W6: =IF(V6="","N/A",IF(V6<TODAY(),"⛔ Expired",IF(V6-TODAY()<=7,"⚠️ Soon","✅ Open"))) | X6: =IF(V6="","",MAX(0,V6-TODAY())) | Y6: SADAR: AI-Powered Spectrum Anomaly Detection for Anti-Drone Threats | Z6: SADAR is an AI-powered autonomous spectrum intelligence platform designed for anti-drone threat detection. The system analyzes RF spectrum signals, detects abnormal patterns, classifies potential drone activities, and provides real-time intelligence through an AI analytics dashboard. | AA6: Python, FastAPI, React, TypeScript, AI/ML Models, Signal Processing, Data Analytics, WebSockets, Docker, REST API | AB6: SADAR AI Team | AC6: 5 | AD6: Yes | AE6: Mohamed Abd Elsalam Mohamed Gharieb | AF6: moghariebai@gmail.com | AG6: +20 01022487565 | AH6: Shortlisted | AI6: Passed First Stage Review and Advanced to Phase 2 | AJ6: Phase 2 Participant | AK6: N/A | AM6: To be added after final presentation recording | AN6: https://github.com/GhariebML/SADAR | AR6: SADAR successfully passed the first stage evaluation of ITC-EGYPT 2026 Anti-Drone Challenge and advanced to Phase 2. The project is currently being prepared for final demonstration including system testing, UI/UX improvements, AI analytics validation, and professional video presentation. Team Leader Location: Montaza District, Alexandria, Egypt. Team Member Aya Ashraf Location: Ibn El Sayar Street, El Kabary, Alexandria, Egypt. | AS6: =COUNTA(G6:H6,M6,Y6,AH6)/5
A7: =IF(B7<>"","SUB-"&TEXT(ROW()+6,"0000"),"") | B7: 2026-06-26 | C7: 2026-06-26 00:00:00 | D7: Admin | E7: 4th Year | F7: Batch 3 | G7: Mohamed Abd Elsalam Mohamed Gharieb | H7: moghariebai@gmail.com | I7: +20 01022487565 | J7: AI & Machine Learning | K7: Alexandria University | L7: Faculty of Engineering | M7: Creativa Alexandria: AI Hackathon – AI for Egypt Real Problems | N7: https://creativa.gov.eg | O7: Creativa Alexandria | P7: AI & Machine Learning | Q7: Egypt | R7: Offline | S7: National | T7: N/A | U7: 2026-05-01 | V7: 2026-06-20 | W7: =IF(V7="","N/A",IF(V7<TODAY(),"⛔ Expired",IF(V7-TODAY()<=7,"⚠️ Soon","✅ Open"))) | X7: =IF(V7="","",MAX(0,V7-TODAY())) | Y7: AeroMind Sentinel | Z7: AeroMind Sentinel is an AI-powered autonomous drone intelligence system that transforms drones from traditional monitoring tools into intelligent agents capable of detecting incidents, analyzing risks, tracking targets, and generating real-time alerts using Computer Vision and AI technologies. | AA7: Artificial Intelligence, Computer Vision, Autonomous Drone Systems, Object Detection, Multi-object Tracking, Real-time Monitoring, AI Decision Making | AB7: AeroMind AI | AC7: 4 | AD7: Yes | AE7: Mohamed Abd Elsalam Mohamed Gharieb | AF7: moghariebai@gmail.com | AG7: +20 01022487565 | AH7: Finalist | AI7: Developed MVP prototype for road safety and smart infrastructure | AJ7: Finalist | AK7: N/A | AR7: AeroMind Sentinel is an AI-powered autonomous drone intelligence system. Validation: road safety and infrastructure challenges validated through research/market analysis; tested solution concept with experts; developed MVP prototype demonstrating AI detection, tracking, monitoring, and alerts. Impact: improving road safety, faster response, smart infrastructure monitoring, supporting AI-driven sustainable cities. Team Members: Mohamed Abd Elsalam Mohamed Gharieb, Aya Mostafa Ali Hassan, Aya Emad Ramadan Elsaby, Eman Mansour Abdel Halim Barrin. | AS7: =COUNTA(G7:H7,M7,Y7,AH7)/5
A8: =IF(B8<>"","SUB-"&TEXT(ROW()+6,"0000"),"") | B8: 2026-06-26 | C8: 2026-06-26 00:00:00 | D8: Admin | E8: 4th Year | F8: Batch 3 | G8: Mohamed Abd Elsalam Mohamed Gharieb | H8: moghariebai@gmail.com | I8: +20 01022487565 | J8: AI & Machine Learning | K8: Alexandria University | L8: Faculty of Engineering | M8: Creativa Alexandria: AI Hackathon – AI for Egypt Real Problems | N8: https://creativa.gov.eg | O8: Creativa Alexandria | P8: AI & Machine Learning | Q8: Egypt | R8: Offline | S8: National | T8: N/A | U8: 2026-05-01 | V8: 2026-06-20 | W8: =IF(V8="","N/A",IF(V8<TODAY(),"⛔ Expired",IF(V8-TODAY()<=7,"⚠️ Soon","✅ Open"))) | X8: =IF(V8="","",MAX(0,V8-TODAY())) | Y8: Bingoo AI | Z8: Bingoo AI is an AI-powered emotional companion for school students that helps detect emotional changes, provide personalized support, and identify early signs of stress using an Agentic AI Multi-Agent System. | AA8: Large Language Models, NLP, Sentiment Analysis, Machine Learning, AI Memory System, Multi-Agent AI System | AB8: Bingoo AI Team | AC8: 4 | AD8: Yes | AE8: Mohamed Abd Elsalam Mohamed Gharieb | AF8: moghariebai@gmail.com | AG8: +20 01022487565 | AH8: Accepted | AI8: Accepted / Approved for Hackathon Participation | AJ8: Participant | AK8: N/A | AL8: None | AM8: None | AN8: None | AO8: None | AP8: None | AQ8: None | AR8: Target Users: School students (12-18 years old). Paying Customers: Private schools, international schools, and educational institutions. Problem: Students face academic pressure, stress, and emotional challenges, while schools lack intelligent tools to understand students’ wellbeing and detect problems early. Solution: An AI companion that communicates naturally with students, understands their emotions, analyzes behavioral patterns, and provides personalized support before problems become serious. AI Architecture: Multi-Agent AI System (Emotion Detection Agent, Conversation Agent, Behavior Analysis Agent, Personal Growth Agent, Safety Agent). Business Model: B2B SaaS. Revenue: School subscriptions, premium student features, educational partnerships. | AS8: =COUNTA(G8:H8,M8,Y8,AH8)/5

Sheet Team Members
A1: 👥 Team Members Directory
A2: Track every team member across all competitions
A4: Team ID | B4: Competition Name | C4: Team Name | D4: Member Name | E4: Email | F4: Phone | G4: Digilians Track | H4: Role | I4: GitHub | J4: LinkedIn | K4: Portfolio | L4: Is Active
A5: =IF(C5<>"","TM-"&TEXT(ROW()+6,"0000"),"") | B5: ITC-EGYPT 2026 | C5: SADAR AI Team | D5: Mohamed Abd Elsalam Mohamed Gharieb | E5: moghariebai@gmail.com | F5: +20 01022487565 | G5: AI & Machine Learning | H5: Leader | I5: https://github.com/GhariebML | L5: Yes
A6: =IF(C6<>"","TM-"&TEXT(ROW()+6,"0000"),"") | B6: ITC-EGYPT 2026 Anti-Drone Challenge | C6: SADAR AI Team | D6: Mohamed Abd Elsalam Mohamed Gharieb | E6: moghariebai@gmail.com | F6: +20 01022487565 | G6: AI & Machine Learning | H6: Leader | I6: https://github.com/GhariebML | L6: Yes
A7: =IF(C7<>"","TM-"&TEXT(ROW()+6,"0000"),"") | B7: ITC-EGYPT 2026 | C7: SADAR AI Team | D7: Goda Emad Goda Elsayed | E7: goda.emad.elsayed@gmail.com | F7: 01126242932 | G7: AI & Machine Learning | H7: AI Developer | I7: https://github.com/godaemad | L7: Yes
A8: =IF(C8<>"","TM-"&TEXT(ROW()+6,"0000"),"") | B8: ITC-EGYPT 2026 Anti-Drone Challenge | C8: SADAR AI Team | D8: Goda Emad Goda Elsayed | E8: goda.emad.elsayed@gmail.com | F8: 01126242932 | G8: AI & Machine Learning | H8: AI Developer | I8: https://github.com/godaemad | L8: Yes
A9: =IF(C9<>"","TM-"&TEXT(ROW()+6,"0000"),"") | B9: ITC-EGYPT 2026 | C9: SADAR AI Team | D9: Aya Emad Ramadan Elsaby | E9: aya.emad.elsaby@gmail.com | F9: 01121897160 | G9: AI & Machine Learning | H9: AI Developer | I9: https://github.com/ayaemad | L9: Yes
A10: =IF(C10<>"","TM-"&TEXT(ROW()+6,"0000"),"") | B10: ITC-EGYPT 2026 Anti-Drone Challenge | C10: SADAR AI Team | D10: Aya Emad Ramadan Elsaby | E10: aya.emad.elsaby@gmail.com | F10: 01121897160 | G10: AI & Machine Learning | H10: AI Developer | I10: https://github.com/ayaemad | L10: Yes
A11: =IF(C11<>"","TM-"&TEXT(ROW()+6,"0000"),"") | B11: ITC-EGYPT 2026 | C11: SADAR AI Team | D11: Eman Mansour Abdel Halim Barrin | E11: eman.mansour.barrin@gmail.com | F11: 01068302915 | G11: AI & Machine Learning | H11: Signal Processing Specialist | I11: https://github.com/emanmansour | L11: Yes
A12: =IF(C12<>"","TM-"&TEXT(ROW()+6,"0000"),"") | B12: ITC-EGYPT 2026 Anti-Drone Challenge | C12: SADAR AI Team | D12: Eman Mansour Abdel Halim Barrin | E12: eman.mansour.barrin@gmail.com | F12: 01068302915 | G12: AI & Machine Learning | H12: Signal Processing Specialist | I12: https://github.com/emanmansour | L12: Yes
A13: =IF(C13<>"","TM-"&TEXT(ROW()+6,"0000"),"") | B13: ITC-EGYPT 2026 | C13: SADAR AI Team | D13: Aya Ashraf Elias AbdelMaksoud | E13: Ayaaeliass@gmail.com | F13: 01277474411 | G13: AI & Machine Learning | H13: UI/UX Designer | I13: https://github.com/Ayaaeliass | L13: Yes
A14: =IF(C14<>"","TM-"&TEXT(ROW()+6,"0000"),"") | B14: ITC-EGYPT 2026 Anti-Drone Challenge | C14: SADAR AI Team | D14: Aya Ashraf Elias AbdelMaksoud | E14: Ayaaeliass@gmail.com | F14: 01277474411 | G14: AI & Machine Learning | H14: UI/UX Designer | I14: https://github.com/Ayaaeliass | L14: Yes
A15: =IF(C15<>"","TM-"&TEXT(ROW()+6,"0000"),"") | B15: Creativa Alexandria: AI Hackathon – AI for Egypt Real Problems | C15: AeroMind AI | D15: Mohamed Abd Elsalam Mohamed Gharieb | E15: moghariebai@gmail.com | F15: +20 01022487565 | G15: AI & Machine Learning | H15: Leader | I15: https://github.com/GhariebML | L15: Yes
A16: =IF(C16<>"","TM-"&TEXT(ROW()+6,"0000"),"") | B16: Creativa Alexandria: AI Hackathon – AI for Egypt Real Problems | C16: AeroMind AI | D16: Aya Mostafa Ali Hassan | E16: aya.mostafa.hassan@gmail.com | F16: 01156565656 | G16: AI & Machine Learning | H16: AI Developer | I16: https://github.com/ayamostafa | L16: Yes
... A18: =IF(C18<>"","TM-"&TEXT(ROW()+6,"0000"),"") | B18: Creativa Alexandria: AI Hackathon – AI for Egypt Real Problems | C18: AeroMind AI | D18: Eman Mansour Abdel Halim Barrin | E18: eman.mansour.barrin@gmail.com | F18: 01068302915 | G18: AI & Machine Learning | H18: Signal Processing Specialist | I18: https://github.com/emanmansour | L18: Yes
A19: =IF(C19<>"","TM-"&TEXT(ROW()+6,"0000"),"") | B19: Creativa Alexandria: AI Hackathon – AI for Egypt Real Problems | C19: Bingoo AI Team | D19: Mohamed Abd Elsalam Mohamed Gharieb | E19: moghariebai@gmail.com | F19: +20 01022487565 | G19: AI & Machine Learning | H19: Leader | I19: https://github.com/GhariebML | J19: https://linkedin.com/in/ghariebml | L19: Yes
A20: =IF(C20<>"","TM-"&TEXT(ROW()+6,"0000"),"") | B20: Creativa Alexandria: AI Hackathon – AI for Egypt Real Problems | C20: Bingoo AI Team | D20: Aya Mostafa Ali Hassan | E20: aya.mostafa.hassan@gmail.com | F20: 01156565656 | G20: AI & Machine Learning | H20: AI Developer | I20: https://github.com/ayamostafa | L20: Yes
A21: =IF(C21<>"","TM-"&TEXT(ROW()+6,"0000"),"") | B21: Creativa Alexandria: AI Hackathon – AI for Egypt Real Problems | C21: Bingoo AI Team | D21: Aya Emad Ramadan Elsaby | E21: aya.emad.elsaby@gmail.com | F21: 01121897160 | G21: AI & Machine Learning | H21: AI Developer | I21: https://github.com/ayaemad | L21: Yes
A22: =IF(C22<>"","TM-"&TEXT(ROW()+6,"0000"),"") | B22: Creativa Alexandria: AI Hackathon – AI for Egypt Real Problems | C22: Bingoo AI Team | D22: Eman Mansour Abdel Halim Barrin | E22: eman.mansour.barrin@gmail.com | F22: 01068302915 | G22: AI & Machine Learning | H22: Signal Processing Specialist | I22: https://github.com/emanmansour | L22: Yes

Sheet Competitions Database
A1: 🏅 Competitions Database
A2: Master list of all competitions tracked by Digilians
A4: Competition ID | B4: Competition Name | C4: Organizer | D4: Website | E4: Registration Link | F4: Category | G4: Country | H4: Online/Offline | I4: Reg. Opens | J4: Reg. Deadline | K4: Submission Deadline | L4: Prize | M4: Announcement Link | N4: Status | O4: Notes
A5: =IF(B5<>"","COMP-"&TEXT(ROW()+6,"0000"),"") | B5: ITC-EGYPT 2026 | C5: ITC Egypt | D5: https://itc-egypt.org | E5: https://itc-egypt.org/register | F5: AI & Machine Learning | G5: Egypt | H5: Online | I5: 2026-01-01 00:00:00 | J5: 2026-04-30 00:00:00 | K5: 2026-07-31 00:00:00 | L5: N/A | M5: https://itc-egypt.org/results | N5: Open | O5: Main event track for artificial intelligence and machine learning submissions.
A6: =IF(B6<>"","COMP-"&TEXT(ROW()+6,"0000"),"") | B6: ITC-EGYPT 2026 Anti-Drone Challenge | C6: ITC Egypt | D6: https://itc-egypt.org | E6: https://itc-egypt.org/register | F6: AI & Machine Learning | G6: Egypt | H6: Online | I6: 2026-01-01 00:00:00 | J6: 2026-04-30 00:00:00 | K6: 2026-07-31 00:00:00 | L6: N/A | M6: https://itc-egypt.org/results | N6: Open | O6: Special challenge track focusing on spectrum intelligence and anti-drone detection systems.
A7: =IF(B7<>"","COMP-"&TEXT(ROW()+6,"0000"),"") | B7: Creativa Alexandria: AI Hackathon – AI for Egypt Real Problems | C7: Creativa Alexandria | D7: https://creativa.gov.eg | E7: https://creativa.gov.eg/register | F7: AI & Machine Learning | G7: Egypt | H7: Offline | I7: 2026-05-01 00:00:00 | J7: 2026-06-15 00:00:00 | K7: 2026-06-20 00:00:00 | L7: N/A | M7: https://creativa.gov.eg/results | N7: Finished | O7: AI Hackathon focusing on real-world problems in Egypt.

Sheet Achievements
A1: 🎖 Achievements Register
A2: Official record of all verified competition achievements
A4: Achievement ID | B4: Competition Name | C4: Team Name | D4: Student Name | E4: Achievement | F4: Ranking | G4: Prize | H4: Achievement Date | I4: Certificate Link | J4: Photos Link | K4: News Link | L4: Verified
A5: =IF(B5<>"","ACH-"&TEXT(ROW()+6,"0000"),"") | B5: ITC-EGYPT 2026 | C5: SADAR AI Team | D5: Mohamed Abd Elsalam Mohamed Gharieb | E5: Passed First Stage Review and Advanced to Phase 2 | F5: Phase 2 Participant | G5: N/A | H5: 2026-06-25 | L5: Yes
A6: =IF(B6<>"","ACH-"&TEXT(ROW()+6,"0000"),"") | B6: ITC-EGYPT 2026 Anti-Drone Challenge | C6: SADAR AI Team | D6: Mohamed Abd Elsalam Mohamed Gharieb | E6: Passed First Stage Review and Advanced to Phase 2 | F6: Phase 2 Participant | G6: N/A | H6: 2026-06-25 | L6: Yes
A7: =IF(B7<>"","ACH-"&TEXT(ROW()+6,"0000"),"") | B7: Creativa Alexandria: AI Hackathon – AI for Egypt Real Problems | C7: AeroMind AI | D7: Mohamed Abd Elsalam Mohamed Gharieb | E7: Developed MVP prototype for road safety and smart infrastructure | F7: Finalist | G7: N/A | H7: 2026-06-20 | L7: Yes
A8: =IF(B8<>"","ACH-"&TEXT(ROW()+6,"0000"),"") | B8: Creativa Alexandria: AI Hackathon – AI for Egypt Real Problems | C8: Bingoo AI Team | D8: Mohamed Abd Elsalam Mohamed Gharieb | E8: Accepted / Approved for Hackathon Participation | F8: Participant | G8: N/A | H8: 2026-06-26 | I8: None | J8: None | K8: None | L8: Yes

Sheet Student Directory
A1: 👤 Student Directory
A2: Complete student registry with competition stats
A4: Student ID | B4: Full Name | C4: Email | D4: Phone | E4: Track | F4: Batch | G4: University | H4: Faculty | I4: GitHub | J4: LinkedIn | K4: Portfolio | L4: Total Competitions | M4: Total Wins | N4: Total Finalists | O4: Current Status
A5: =IF(B5<>"","STD-"&TEXT(ROW()+6,"0000"),"") | B5: Mohamed Abd Elsalam Mohamed Gharieb | C5: moghariebai@gmail.com | D5: +20 01022487565 | E5: AI & Machine Learning | F5: Batch 3 | G5: Alexandria University | H5: Faculty of Engineering | I5: https://github.com/GhariebML | J5: https://linkedin.com/in/ghariebml | L5: =COUNTIF('Team Members'!D$5:D$2000, B5) | M5: =COUNTIFS(Achievements!D$5:D$2000, B5, Achievements!F$5:F$2000, "Winner") | N5: =COUNTIFS(Achievements!D$5:D$2000, B5, Achievements!F$5:F$2000, "Finalist") | O5: Active
A6: =IF(B6<>"","STD-"&TEXT(ROW()+6,"0000"),"") | B6: Goda Emad Goda Elsayed | C6: goda.emad.elsayed@gmail.com | D6: 01126242932 | E6: AI & Machine Learning | F6: Batch 3 | G6: Alexandria University | H6: Faculty of Engineering | I6: https://github.com/godaemad | L6: =COUNTIF('Team Members'!D$5:D$2000, B6) | M6: =COUNTIFS(Achievements!D$5:D$2000, B6, Achievements!F$5:F$2000, "Winner") | N6: =COUNTIFS(Achievements!D$5:D$2000, B6, Achievements!F$5:F$2000, "Finalist") | O6: Active
A7: =IF(B7<>"","STD-"&TEXT(ROW()+6,"0000"),"") | B7: Aya Emad Ramadan Elsaby | C7: aya.emad.elsaby@gmail.com | D7: 01121897160 | E7: AI & Machine Learning | F7: Batch 3 | G7: Alexandria University | H7: Faculty of Engineering | I7: https://github.com/ayaemad | L7: =COUNTIF('Team Members'!D$5:D$2000, B7) | M7: =COUNTIFS(Achievements!D$5:D$2000, B7, Achievements!F$5:F$2000, "Winner") | N7: =COUNTIFS(Achievements!D$5:D$2000, B7, Achievements!F$5:F$2000, "Finalist") | O7: Active
A8: =IF(B8<>"","STD-"&TEXT(ROW()+6,"0000"),"") | B8: Eman Mansour Abdel Halim Barrin | C8: eman.mansour.barrin@gmail.com | D8: 01068302915 | E8: AI & Machine Learning | F8: Batch 3 | G8: Alexandria University | H8: Faculty of Engineering | I8: https://github.com/emanmansour | L8: =COUNTIF('Team Members'!D$5:D$2000, B8) | M8: =COUNTIFS(Achievements!D$5:D$2000, B8, Achievements!F$5:F$2000, "Winner") | N8: =COUNTIFS(Achievements!D$5:D$2000, B8, Achievements!F$5:F$2000, "Finalist") | O8: Active
A9: =IF(B9<>"","STD-"&TEXT(ROW()+6,"0000"),"") | B9: Aya Ashraf Elias AbdelMaksoud | C9: Ayaaeliass@gmail.com | D9: 01277474411 | E9: AI & Machine Learning | F9: Batch 3 | G9: Alexandria University | H9: Faculty of Engineering | I9: https://github.com/Ayaaeliass | L9: =COUNTIF('Team Members'!D$5:D$2000, B9) | M9: =COUNTIFS(Achievements!D$5:D$2000, B9, Achievements!F$5:F$2000, "Winner") | N9: =COUNTIFS(Achievements!D$5:D$2000, B9, Achievements!F$5:F$2000, "Finalist") | O9: Active
A10: =IF(B10<>"","STD-"&TEXT(ROW()+6,"0000"),"") | B10: Aya Mostafa Ali Hassan | C10: aya.mostafa.hassan@gmail.com | D10: 01156565656 | E10: AI & Machine Learning | F10: Batch 3 | G10: Alexandria University | H10: Faculty of Engineering | I10: https://github.com/ayamostafa | L10: =COUNTIF('Team Members'!D$5:D$2000, B10) | M10: =COUNTIFS(Achievements!D$5:D$2000, B10, Achievements!F$5:F$2000, "Winner") | N10: =COUNTIFS(Achievements!D$5:D$2000, B10, Achievements!F$5:F$2000, "Finalist") | O10: Active

Sheet Dashboard
A1: 🏆 DIGILIANS ACHIEVEMENT PORTAL — DASHBOARD
A2: Auto-calculated from live data | Last Refreshed: 26 June 2026
R3: Track | S3: Count | U3: Status | V3: Count
A4: 👤 Total Students | C4: 🏅 Total Competitions | E4: 📋 Total Submissions | G4: 👥 Total Team Members | I4: 🏆 Total Winners | K4: 🎖 Total Finalists | M4: ✅ Verified Achievements | O4: 🔓 Open Competitions | R4: AI & Machine Learning | S4: =COUNTIF('Competition Submissions'!J5:J2000,"AI & Machine Learning") | U4: Winner | V4: =COUNTIF('Competition Submissions'!AH5:AH2000,"Winner")
A5: =COUNTA('Student Directory'!B5:B2000) | C5: =COUNTA('Competitions Database'!B5:B2000) | E5: =COUNTA('Competition Submissions'!B5:B2000) | G5: =COUNTA('Team Members'!D5:D2000) | I5: =COUNTIF('Competition Submissions'!AH5:AH2000,"Winner") | K5: =COUNTIF('Competition Submissions'!AH5:AH2000,"Finalist") | M5: =COUNTIF(Achievements!L5:L2000,"Yes") | O5: =COUNTIF('Competitions Database'!N5:N2000,"Open") | R5: Data Science | S5: =COUNTIF('Competition Submissions'!J5:J2000,"Data Science") | U5: Finalist | V5: =COUNTIF('Competition Submissions'!AH5:AH2000,"Finalist")
R6: Web Development | S6: =COUNTIF('Competition Submissions'!J5:J2000,"Web Development") | U6: Shortlisted | V6: =COUNTIF('Competition Submissions'!AH5:AH2000,"Shortlisted")
R7: Mobile Development | S7: =COUNTIF('Competition Submissions'!J5:J2000,"Mobile Development") | U7: Under Review | V7: =COUNTIF('Competition Submissions'!AH5:AH2000,"Under Review")
A8: 📊 PARTICIPATION BY TRACK | J8: 🏅 TOP STUDENTS LEADERBOARD | R8: Cybersecurity | S8: =COUNTIF('Competition Submissions'!J5:J2000,"Cybersecurity") | U8: Registered | V8: =COUNTIF('Competition Submissions'!AH5:AH2000,"Registered")
A9: Track | E9: Track | I9: Count | J9: # | K9: Student Name | L9: Competitions | M9: Wins | N9: Finals | R9: Cloud Computing | S9: =COUNTIF('Competition Submissions'!J5:J2000,"Cloud Computing") | U9: Rejected | V9: =COUNTIF('Competition Submissions'!AH5:AH2000,"Rejected")
A10: AI & Machine Learning | E10: =COUNTIF('Competition Submissions'!J5:J2000,"AI & Machine Learning") | J10: 1 | K10: ='Student Directory'!B5 | L10: ='Student Directory'!L5 | M10: ='Student Directory'!M5 | N10: ='Student Directory'!N5 | R10: UI/UX Design | S10: =COUNTIF('Competition Submissions'!J5:J2000,"UI/UX Design")
A11: Data Science | E11: =COUNTIF('Competition Submissions'!J5:J2000,"Data Science") | J11: 2 | K11: ='Student Directory'!B6 | L11: ='Student Directory'!L6 | M11: ='Student Directory'!M6 | N11: ='Student Directory'!N6 | R11: Business Technology | S11: =COUNTIF('Competition Submissions'!J5:J2000,"Business Technology")
A12: Web Development | E12: =COUNTIF('Competition Submissions'!J5:J2000,"Web Development") | J12: 3 | K12: ='Student Directory'!B7 | L12: ='Student Directory'!L7 | M12: ='Student Directory'!M7 | N12: ='Student Directory'!N7 | R12: Embedded Systems | S12: =COUNTIF('Competition Submissions'!J5:J2000,"Embedded Systems")
A13: Mobile Development | E13: =COUNTIF('Competition Submissions'!J5:J2000,"Mobile Development") | J13: 4 | K13: ='Student Directory'!B8 | L13: ='Student Directory'!L8 | M13: ='Student Directory'!M8 | N13: ='Student Directory'!N8 | R13: Other | S13: =COUNTIF('Competition Submissions'!J5:J2000,"Other")
A14: Cybersecurity | E14: =COUNTIF('Competition Submissions'!J5:J2000,"Cybersecurity") | J14: 5 | K14: ='Student Directory'!B9 | L14: ='Student Directory'!L9 | M14: ='Student Directory'!M9 | N14: ='Student Directory'!N9
A16: 📈 COMPETITION SUCCESS METRICS | J16: 📅 MONTHLY REGISTRATIONS
A17: Total Submissions | E17: =COUNTA('Competition Submissions'!B5:B2000) | J17: Jan | K17: Feb | L17: Mar | M17: Apr | N17: May | O17: Jun | P17: Jul
A18: Winners | E18: =COUNTIF('Competition Submissions'!AH5:AH2000,"Winner") | J18: =SUMPRODUCT((MONTH('Competition Submissions'!B5:B2000)=1)*(YEAR('Competition Submissions'!B5:B2000)=2026)) | K18: =SUMPRODUCT((MONTH('Competition Submissions'!B5:B2000)=2)*(YEAR('Competition Submissions'!B5:B2000)=2026)) | L18: =SUMPRODUCT((MONTH('Competition Submissions'!B5:B2000)=3)*(YEAR('Competition Submissions'!B5:B2000)=2026)) | M18: =SUMPRODUCT((MONTH('Competition Submissions'!B5:B2000)=4)*(YEAR('Competition Submissions'!B5:B2000)=2026)) | N18: =SUMPRODUCT((MONTH('Competition Submissions'!B5:B2000)=5)*(YEAR('Competition Submissions'!B5:B2000)=2026)) | O18: =SUMPRODUCT((MONTH('Competition Submissions'!B5:B2000)=6)*(YEAR('Competition Submissions'!B5:B2000)=2026)) | P18: =SUMPRODUCT((MONTH('Competition Submissions'!B5:B2000)=7)*(YEAR('Competition Submissions'!B5:B2000)=2026))
A19: Finalists | E19: =COUNTIF('Competition Submissions'!AH5:AH2000,"Finalist")
A20: Shortlisted | E20: =COUNTIF('Competition Submissions'!AH5:AH2000,"Shortlisted")
A21: Rejected | E21: =COUNTIF('Competition Submissions'!AH5:AH2000,"Rejected")
A22: Win Rate | E22: =IF(COUNTA('Competition Submissions'!B5:B2000)=0,0,COUNTIF('Competition Submissions'!AH5:AH2000,"Winner")/COUNTA('Competition Submissions'!B5:B2000))

Sheet Drop-Down Lists
A1: 🗂 Digilians — Reference Drop-Down Lists
A2: All dropdown values used across the workbook
A3: Tracks | B3: Competition Categories | C3: Countries | D3: Roles | E3: Competition Status | F3: Achievement Types | G3: Universities | H3: Academic Years | I3: Batches | J3: Yes/No | K3: Comp Type | L3: Comp Reg Status | M3: Student Status | N3: Verified
A4: AI & Machine Learning | B4: AI & Machine Learning | C4: Egypt | D4: Leader | E4: Registered | F4: 1st Place | G4: Cairo University | H4: 1st Year | I4: Batch 1 | J4: Yes | K4: Online | L4: Upcoming | M4: Active | N4: Yes
A5: Data Science | B5: Data Science | C5: Saudi Arabia | D5: Developer | E5: Team Formed | F5: 2nd Place | G5: Ain Shams University | H5: 2nd Year | I5: Batch 2 | J5: No | K5: Offline | L5: Open | M5: Inactive | N5: No
A6: Web Development | B6: Web Development | C6: UAE | D6: AI Engineer | E6: Idea Submitted | F6: 3rd Place | G6: Alexandria University | H6: 3rd Year | I6: Batch 3 | K6: Hybrid | L6: Closed | M6: Graduated
A7: Mobile Development | B7: Mobile Application | C7: Jordan | D7: Data Scientist | E7: Proposal Submitted | F7: Top 5 | G7: Mansoura University | H7: 4th Year | I7: Batch 4 | L7: Finished
A8: Cybersecurity | B8: Cybersecurity | C8: Kuwait | D8: Backend | E8: MVP Completed | F8: Top 10 | G8: Helwan University | H8: 5th Year | I8: Batch 5
A9: Cloud Computing | B9: Innovation | C9: Qatar | D9: Frontend | E9: Under Review | F9: Top 20 | G9: Benha University | H9: Graduate | I9: Batch 6
A10: UI/UX Design | B10: Entrepreneurship | C10: Morocco | D10: UI/UX | E10: Shortlisted | F10: Finalist | G10: Zagazig University | I10: Batch 7
A11: Business Technology | B11: Robotics | C11: Tunisia | D11: Business | E11: Top 100 | F11: Honorable Mention | G11: Suez Canal University | I11: Batch 8
A12: Embedded Systems | B12: Design | C12: Germany | D12: Marketing | E12: Top 50 | F12: Participant | G12: Menoufia University | I12: Batch 9
A13: Other | B13: Research | C13: USA | D13: Research | E13: Top 20 | G13: South Valley University | I13: Batch 10
B14: Open Source | C14: UK | D14: Other | E14: Finalist | G14: Other | I14: Batch 11
B15: Other | C15: France | E15: Winner | I15: Batch 12
C16: Canada | E16: Rejected | I16: Batch 13
C17: Netherlands | I17: Batch 14
C18: Singapore | I18: Batch 15
C19: International
